# 14. 비동기 - 예외 처리(then, catch, finally)

[Promis MDN](https://developer.mozilla.org/ko/docs/Web/JavaScript/Reference/Global_Objects/Promise)

- 비동기 패턴에 대한 이해

<br/>

## 14.1. Promise

- **`Promise`** 객체는 비동기 작업이 맞이할 미래의 완료 또는 실패와 그 결과 값을 나타냅니다.
- 즉, `Promise`는 무엇인가의 로직을 처리가 완료가 될 때까지 기다린다는 의미로, 기다리고 난 이후의 실행을 약속한다.
- 따라서, `약속의 객체`라고 불린다.
- `Promise`는 다음 중 하나의 상태를 가집니다.
  - 대기(*pending)*: 이행하지도, 거부하지도 않은 초기 상태.
  - 이행(*fulfilled)*: 연산이 성공적으로 완료됨.
  - 거부(*rejected)*: 연산이 실패함.

<br/>

## 14.2. [인스턴스 메서드](https://developer.mozilla.org/ko/docs/Web/JavaScript/Reference/Global_Objects/Promise#인스턴스_메서드)

[마이크로태스크 안내서](https://developer.mozilla.org/ko/docs/Web/API/HTML_DOM_API/Microtask_guide)를 방문해 프로미스 인스턴스 메서드가 마이크로태스크 큐와 서비스를 이용하는 방법을 알아보세요.

- [`Promise.prototype.catch()` (en-US)](https://developer.mozilla.org/en-US/docs/Web/JavaScript/Reference/Global_Objects/Promise/catch)

  프로미스에 거부 처리기 콜백을 추가하고, 콜백이 호출될 경우 그 반환값으로 이행하며 호출되지 않을 경우, 즉 이전 프로미스가 이행하는 경우 이행한 값을 그대로 사용해 이행하는 새로운 프로미스를 반환합니다.

- [`Promise.prototype.then()`](https://developer.mozilla.org/ko/docs/Web/JavaScript/Reference/Global_Objects/Promise/then)

  프로미스에 이행과 거부 처리기 콜백을 추가하고, 콜백이 호출될 경우 그 반환값으로 이행하며 호출되지 않을 경우(`onFulfilled`, `onRejected` 중 상태에 맞는 콜백이 함수가 아닐 경우) 처리된 값과 상태 그대로 처리되는 새로운 프로미스를 반환합니다.

- [`Promise.prototype.finally()`](https://developer.mozilla.org/ko/docs/Web/JavaScript/Reference/Global_Objects/Promise/finally)

  프로미스의 이행과 거부 여부에 상관없이 처리될 경우 항상 호출되는 처리기 콜백을 추가하고, 이행한 값 그대로 이행하는 새로운 프로미스를 반환합니다.

<br/>

### 14.2.1. Promise 프로토타입 - then, catch, finally

- `async / await` 의 경우 ES8 이다. 하지만, `Promise`라는 개념은 `ES6` 의 개념이다. `async / await` 가 편리하지만, 이것을 사용하지 못하는 경우에는 어떠한 방법으로 비동기를 처리할 수 있을까?
- `then, catch, finally` 라는 Promise 객체에서 사용할 수 있는 메서드들이 있다.

#### 1) Promise - then()

```js
function a(){
  return new Promise((resolve)=>{
    setTimeout(()=>{
      console.log('A')
      resolve()
    },1000)
  })
}

function test(){
  const promise = a()
  promise.then(()=>{
    console.log('B')
  })
}

test()
```

- 여러개의 메서드를 `then()` 으로 메서드 체이닝으로 연결해보기

```js
function a(){
  return new Promise((resolve)=>{
    setTimeout(()=>{
      console.log('A')
      resolve()
    },1000)
  })
}
function b(){
  return new Promise((resolve)=>{
    setTimeout(()=>{
      console.log('B')
      resolve()
    },1000)
  })
}
function c(){
  return new Promise((resolve)=>{
    setTimeout(()=>{
      console.log('C')
      resolve()
    },1000)
  })
}
function d(){
  return new Promise((resolve)=>{
    setTimeout(()=>{
      console.log('D')
      resolve()
    },1000)
  })
}

function test(){
  a().then(()=>{
    b().then(()=>{
      c().then(()=>{
        d().then(()=>{
          console.log('Done!')
        })
      })
    })
  })
}

test()
```

- 하지만, 이러한 패턴은 `콜백 지옥` 과 유사하고, 복잡하고, 권장하지 않는다.
- 이러한 문제를 해결하기 위해서?

```js
function test(){
  a().then(()=>{
    return b()
  }).then(()=>{
    return c()
  }).then(()=>{
    return d()
  }).then(()=>{
    console.log('Done!')
  })
}

test()
```

- 화살표 함수에서 return을 생략할 수 있으므로,
- 더 깔끔하게 한다면,

```js
function test(){
  a()
    .then(()=>b())
    .then(()=>c())
    .then(()=>d())
    .then(()=>{
      console.log('Done!')
    })
}
test()
```

- 위와 같은 형태로 깔끔하게 구현할 수 있다. 

<br/>

#### 2) Promise - catch

```js
function a(number){
  // 1. reject
  return new Promise((resolve, reject)=>{
    // 2.
    if (number>4){
      reject()
      // 4.
      return
    }
    setTimeout(()=>{
      console.log('A')
      resolve()
    },1000)
  })
}

function test(){
   // 3.
  a(5)
    .then(()=>{
      console.log('resolve!')
    })
    .catch(()=>{
      console.log('Reject!')
    })
}
test()

// Reject!
// A
```

1. `reject` 는  `Promise`의 callback 내부의 로직이 정상적으로 출력이 될 수 없을 때, `resolve` 처럼 호출 한다.
2. `e.g. :` number라는 매개변수가 4보다 클 경우 로직을 정상적으로 처리 하지 않겠다는 의미이다. 
   - `reject` 이라는 매개변수는 거부의 의미로 Promise의 callback은 더이상 동작하지 않는다.
   - 이행 :  `Promise`의 로직이 완료가 됐을 때
   - 거부 :  `reject`이 실행 됐을 때, 로직이 거부가 될 때

3. `catch` 라는 메서드를 체이닝 형태로 붙여 준다.
   - number가 4보다 크므로, `reject()` 이라는 매개변수가 실행된다. 
   - 따라서, `resolve()` 는 실행이 되지 않으므로, `.then()` 은 동작하지 않게 된다.
4. `Reject` 만 출력이 되도록 return으로 마무리를 한다.

<br/>

#### 3) Promise - finally

```js
function a(number){
  // 1. reject
  return new Promise((resolve, reject)=>{
    // 2.
    if (number>4){
      reject()
      // 4.
      return
    }
    setTimeout(()=>{
      console.log('A')
      resolve()
    },1000)
  })
}

function test(){
   // 3.
  a(5)
    .then(()=>{
      console.log('resolve!')
    })
    .catch(()=>{
      console.log('Reject!')
    })
    // 5. finally
    .finally(()=>{
      console.log('Done!')
    })
}
test()

// Reject!
// Done!
```

5. `finally` 는 이름 그대로 마지막에 실행할 내용을 나타낸다.  
   - `catch` 가 실행이 되고, `then()` 이 실행이 안 돼도, `finally` 는 실행이 되고
   - `then()`이  실행이 되고, `catch` 가 실행이 안 돼도, `finally` 는 실행이 되고

<br/>

#### 4) async / await 비동기로 적용한다면 - `try / catch / finally 구문`

```js
function a(number){
  return new Promise((resolve, reject)=>{
    if (number>4){
      reject()
      return
    }
    setTimeout(()=>{
      console.log('A')
      resolve()
    },1000)
  })
}


async function test(){
  // a(2)
  //   .then(()=>{
  //     console.log('resolve!')
  //   })
  //   .catch(()=>{
  //     console.log('Reject!')
  //   })
  //   .finally(()=>{
  //     console.log('Done!')
  //   })
  // 1. try / catch 구문
  try {
    await a(8)
    console.log('Resolve!')
  } catch (error){
    console.log('Reject')
  } finally {
    console.log('Done!')
  }
}
test()

// Reject!
// Done!
```

1.  `try` 에는 에러가 발생할 수 도 있는 구문
2. `catch` 에는 에러가 발생했을 때, 그 내용을 처리하는 구문
3. `finally` 에는 마지막에 로직이 끝났을 때, 처리 구문